Workbook

Sheet ClaimIndex
A1: ClaimIndex — every public claim, its evidence and status | H1: About / navigation →
A2: A source match is not clinical validation. Status counts below are live COUNTIF formulas. Workbook value = formula over Sources; Check = stated value within half a unit of its last decimal of the workbook value.
B3: Status | C3: Claims
B4: supported | C4: =COUNTIF($E$16:$E$288,B4) | D4: The stated value or fact matches a saved artifact, report or dataset record named in Sources.
B5: supported-arithmetic | C5: =COUNTIF($E$16:$E$288,B5) | D5: Follows by arithmetic from stated definitions (formula shown); no experiment involved.
B6: tested | C6: =COUNTIF($E$16:$E$288,B6) | D6: Behaviour covered by a test that passed in the saved test record (JUnit) named in the row.
B7: implemented | C7: =COUNTIF($E$16:$E$288,B7) | D7: Present in code or configuration only; no saved passing test is cited for the behaviour.
B8: negative-result | C8: =COUNTIF($E$16:$E$288,B8) | D8: A saved study result that did not meet its declared bar; reported as negative, not as a gain.
B9: author-reported | C9: =COUNTIF($E$16:$E$288,B9) | D9: Stated by the team without a saved log, artifact or primary source in the repository.
B10: proposed/illustrative | C10: =COUNTIF($E$16:$E$288,B10) | D10: A proposal, scenario or illustration; not an evidential claim.
B11: pending | C11: =COUNTIF($E$16:$E$288,B11) | D11: Evidence is not on this installation or a primary-source check is still to be done.
B12: unsupported/contradicted | C12: =COUNTIF($E$16:$E$288,B12) | D12: The saved source disagrees with the stated value, or no support exists.
B13: total | C13: =COUNTA($A$16:$A$288)
A15: Claim ID | B15: Exact claim | C15: Location(s) | D15: Evaluation / model scope | E15: Status | F15: Source IDs | G15: Workbook value (formula) | H15: Stated value | I15: Decimals | J15: Check | K15: Material limitation | L15: Unresolved action | M15: Manifest group | check
A16: C-SRV-01 | B16: The app serves lightgbm.dyn-prof-v2.gt-primary-2026-10-13-fusion for recorded data | C16: README.md (Results at a glance); reports/evidence_manifest.md; README §7 | D16: Software configuration | E16: supported | F16: reg.serving; registry | G16: — | H16: — | J16: — | M16: serving-identity | serving model (recorded data)
A17: C-FC-01 | B17: Serving MAE 12.96 mg/dL at 30 min | C17: README.md (Results at a glance); reports/evidence_manifest.md; Deck s11; Deck s13; narration scene 8 | D17: Serving model, final test segment (later recordings of the same 14 people; retrospective, inspected) | E17: supported | F17: fus.serv.mae30 | G17: =IF(AND(ISNUMBER(Sources!$C$25)),Sources!$C$25,"unavailable") | H17: 12.96 | I17: 2 | J17: =IF(ISNUMBER(G17),IF(ABS(G17-H17)<=0.5*10^(-I17)+1E-9,"matches","MISMATCH"),"pending") | K17: Same 14 people as training; macro over participants | M17: demo-forecast | MAE 30
A18: C-FC-02 | B18: Serving MAE 20.26 mg/dL at 60 min | C18: README.md (Results at a glance); reports/evidence_manifest.md; Deck s11; Deck s13 | D18: Serving model, final test segment (later recordings of the same 14 people; retrospective, inspected) | E18: supported | F18: fus.serv.mae60 | G18: =IF(AND(ISNUMBER(Sources!$C$29)),Sources!$C$29,"unavailable") | H18: 20.26 | I18: 2 | J18: =IF(ISNUMBER(G18),IF(ABS(G18-H18)<=0.5*10^(-I18)+1E-9,"matches","MISMATCH"),"pending") | K18: Same 14 people as training | M18: demo-forecast | MAE 60
A19: C-FC-03 | B19: Persistence MAE 14.84 mg/dL at 30 min (same origins) | C19: README.md (Results at a glance); reports/evidence_manifest.md; Deck s11; Deck s13 | D19: Serving model, final test segment (later recordings of the same 14 people; retrospective, inspected) | E19: supported | F19: fus.pers.mae30 | G19: =IF(AND(ISNUMBER(Sources!$C$5)),Sources!$C$5,"unavailable") | H19: 14.84 | I19: 2 | J19: =IF(ISNUMBER(G19),IF(ABS(G19-H19)<=0.5*10^(-I19)+1E-9,"matches","MISMATCH"),"pending") | M19: demo-forecast | persistence 30
A20: C-FC-04 | B20: Persistence MAE 23.23 mg/dL at 60 min (same origins) | C20: README.md (Results at a glance); reports/evidence_manifest.md; Deck s11; Deck s13 | D20: Serving model, final test segment (later recordings of the same 14 people; retrospective, inspected) | E20: supported | F20: fus.pers.mae60 | G20: =IF(AND(ISNUMBER(Sources!$C$7)),Sources!$C$7,"unavailable") | H20: 23.23 | I20: 2 | J20: =IF(ISNUMBER(G20),IF(ABS(G20-H20)<=0.5*10^(-I20)+1E-9,"matches","MISMATCH"),"pending") | M20: demo-forecast | persistence 60
A21: C-WN-01 | B21: 61 new high-glucose onsets warned (60-min warning) | C21: README.md (Results at a glance); reports/evidence_manifest.md; Deck s13 | D21: Serving model, final test segment (later recordings of the same 14 people; retrospective, inspected) | E21: supported | F21: fus.ev.detected_onsets | G21: =IF(AND(ISNUMBER(Sources!$C$62)),Sources!$C$62,"unavailable") | H21: 61 | I21: 0 | J21: =IF(ISNUMBER(G21),IF(ABS(G21-H21)<=0.5*10^(-I21)+1E-9,"matches","MISMATCH"),"pending") | K21: Research event definition; not triage | M21: demo-warning | onsets warned
A22: C-WN-02 | B22: 64 new high-glucose onsets in the final test segment | C22: README.md (Results at a glance); reports/evidence_manifest.md; Deck s13 | D22: Serving model, final test segment (later recordings of the same 14 people; retrospective, inspected) | E22: supported | F22: fus.ev.true_onsets | G22: =IF(AND(ISNUMBER(Sources!$C$61)),Sources!$C$61,"unavailable") | H22: 64 | I22: 0 | J22: =IF(ISNUMBER(G22),IF(ABS(G22-H22)<=0.5*10^(-I22)+1E-9,"matches","MISMATCH"),"pending") | K22: Onsets ≠ origins ≠ participants | M22: demo-warning | onsets
A23: C-WN-03 | B23: 40 false alarms | C23: README.md (Results at a glance); reports/evidence_manifest.md | D23: Serving model, final test segment (later recordings of the same 14 people; retrospective, inspected) | E23: supported | F23: fus.ev.false_alarm_episodes | G23: =IF(AND(ISNUMBER(Sources!$C$64)),Sources!$C$64,"unavailable") | H23: 40 | I23: 0 | J23: =IF(ISNUMBER(G23),IF(ABS(G23-H23)<=0.5*10^(-I23)+1E-9,"matches","MISMATCH"),"pending") | M23: demo-warning | false alarms
A24: C-WN-04 | B24: 1.49 false alarms per observed patient-day | C24: README.md (Results at a glance); reports/evidence_manifest.md; Deck s13 | D24: Serving model, final test segment (later recordings of the same 14 people; retrospective, inspected) | E24: supported | F24: fus.ev.false_alarm_episodes; fus.ev.observed_patient_days | G24: =IF(AND(ISNUMBER(Sources!$C$64),ISNUMBER(Sources!$C$67)),Sources!$C$64/Sources!$C$67,"unavailable") | H24: 1.49 | I24: 2 | J24: =IF(ISNUMBER(G24),IF(ABS(G24-H24)<=0.5*10^(-I24)+1E-9,"matches","MISMATCH"),"pending") | K24: Denominator = observed patient-days from saved event metadata (approximate time base: issued origins × 5 min) | M24: demo-warning | false alarms per observed day
A25: C-WN-05 | B25: Median forecast lead 30 min among detected onsets | C25: README.md (Results at a glance); reports/evidence_manifest.md; narration metric card | D25: Serving model, final test segment (later recordings of the same 14 people; retrospective, inspected) | E25: supported | F25: fus.ev.qualified_lead_median | G25: =IF(AND(ISNUMBER(Sources!$C$70)),Sources!$C$70,"unavailable") | H25: 30 | I25: 0 | J25: =IF(ISNUMBER(G25),IF(ABS(G25-H25)<=0.5*10^(-I25)+1E-9,"matches","MISMATCH"),"pending") | K25: Denominator = detected onsets with a qualified lead (61), not all onsets | M25: demo-warning | median forecast lead
A26: C-WN-06 | B26: Warning active at 11.8 % of eligible times | C26: README.md (Results at a glance); reports/evidence_manifest.md; reports/warning_time_share.md; narration metric card | D26: Serving model, final test segment (later recordings of the same 14 people; retrospective, inspected) | E26: supported | F26: wu.firing; wu.eligible | G26: =IF(AND(ISNUMBER(Sources!$C$128),ISNUMBER(Sources!$C$129)),Sources!$C$128/Sources!$C$129*100,"unavailable") | H26: 11.8 | I26: 1 | J26: =IF(ISNUMBER(G26),IF(ABS(G26-H26)<=0.5*10^(-I26)+1E-9,"matches","MISMATCH"),"pending") | K26: Post-hoc diagnostic | M26: demo-time-in-warning | share of eligible times warning
A27: C-RG-01 | B27: Served 80 % ranges covered 74.2 % at 30 min (under-coverage) | C27: README.md (Results at a glance); reports/evidence_manifest.md; Deck s10; Deck s11; Deck s14 | D27: Serving model, final test segment (later recordings of the same 14 people; retrospective, inspected) | E27: supported | F27: fus.iv.coverage30 | G27: =IF(AND(ISNUMBER(Sources!$C$79)),Sources!$C$79*100,"unavailable") | H27: 74.2 | I27: 1 | J27: =IF(ISNUMBER(G27),IF(ABS(G27-H27)<=0.5*10^(-I27)+1E-9,"matches","MISMATCH"),"pending") | K27: Pooled over origins; per-person coverage varies | M27: demo-ranges | demo coverage 30
A28: C-RG-02 | B28: Served 80 % ranges covered 74.0 % at 60 min (under-coverage) | C28: README.md (Results at a glance); reports/evidence_manifest.md; Deck s11; Deck s14 | D28: Serving model, final test segment (later recordings of the same 14 people; retrospective, inspected) | E28: supported | F28: fus.iv.coverage60 | G28: =IF(AND(ISNUMBER(Sources!$C$85)),Sources!$C$85*100,"unavailable") | H28: 74 | I28: 1 | J28: =IF(ISNUMBER(G28),IF(ABS(G28-H28)<=0.5*10^(-I28)+1E-9,"matches","MISMATCH"),"pending") | M28: demo-ranges | demo coverage 60
A29: C-RG-03 | B29: Research procedure ranges covered 80.1 % at 30 min (people held out) | C29: README.md (Results at a glance); reports/evidence_manifest.md | D29: Participant-held-out internal (14 CGMacros people, each held out once; previously inspected) | E29: supported | F29: nest.cov30 | G29: =IF(AND(ISNUMBER(Sources!$C$197)),Sources!$C$197*100,"unavailable") | H29: 80.1 | I29: 1 | J29: =IF(ISNUMBER(G29),IF(ABS(G29-H29)<=0.5*10^(-I29)+1E-9,"matches","MISMATCH"),"pending") | K29: Different procedure from the served model | M29: demo-ranges | nested research coverage 30
A30: C-RG-04 | B30: Research procedure ranges covered 78.8 % at 60 min (people held out) | C30: README.md (Results at a glance); reports/evidence_manifest.md | D30: Participant-held-out internal (14 CGMacros people, each held out once; previously inspected) | E30: supported | F30: nest.cov60 | G30: =IF(AND(ISNUMBER(Sources!$C$209)),Sources!$C$209*100,"unavailable") | H30: 78.8 | I30: 1 | J30: =IF(ISNUMBER(G30),IF(ABS(G30-H30)<=0.5*10^(-I30)+1E-9,"matches","MISMATCH"),"pending") | M30: demo-ranges | nested research coverage 60
A31: C-NS-01 | B31: Research candidate MAE 13.88 at 30 min (D-032) | C31: README.md (Results at a glance); reports/evidence_manifest.md; Deck s11; narration scene 8 | D31: Participant-held-out internal (14 CGMacros people, each held out once; previously inspected) | E31: supported | F31: nest.sel.mae30 | G31: =IF(AND(ISNUMBER(Sources!$C$191)),Sources!$C$191,"unavailable") | H31: 13.88 | I31: 2 | J31: =IF(ISNUMBER(G31),IF(ABS(G31-H31)<=0.5*10^(-I31)+1E-9,"matches","MISMATCH"),"pending") | K31: Not served; cohort previously inspected | M31: nested-forecast | MAE 30
A32: C-NS-02 | B32: Research candidate MAE 22.30 at 60 min (D-032) | C32: README.md (Results at a glance); reports/evidence_manifest.md; Deck s11 | D32: Participant-held-out internal (14 CGMacros people, each held out once; previously inspected) | E32: supported | F32: nest.sel.mae60 | G32: =IF(AND(ISNUMBER(Sources!$C$192)),Sources!$C$192,"unavailable") | H32: 22.3 | I32: 2 | J32: =IF(ISNUMBER(G32),IF(ABS(G32-H32)<=0.5*10^(-I32)+1E-9,"matches","MISMATCH"),"pending") | K32: Source value 22.305 is an exact rounding tie at the source's own precision; stated 22.3 is one of its two valid roundings | M32: nested-forecast | MAE 60
A33: C-NS-03 | B33: Nested persistence 15.34 at 30 min | C33: README.md (Results at a glance); reports/evidence_manifest.md; Deck s11 | D33: Participant-held-out internal (14 CGMacros people, each held out once; previously inspected) | E33: supported | F33: nest.pers.mae30 | G33: =IF(AND(ISNUMBER(Sources!$C$193)),Sources!$C$193,"unavailable") | H33: 15.34 | I33: 2 | J33: =IF(ISNUMBER(G33),IF(ABS(G33-H33)<=0.5*10^(-I33)+1E-9,"matches","MISMATCH"),"pending") | M33: nested-forecast | persistence 30
A34: C-NS-04 | B34: Nested persistence 24.47 at 60 min | C34: README.md (Results at a glance); reports/evidence_manifest.md; Deck s11 | D34: Participant-held-out internal (14 CGMacros people, each held out once; previously inspected) | E34: supported | F34: nest.pers.mae60 | G34: =IF(AND(ISNUMBER(Sources!$C$194)),Sources!$C$194,"unavailable") | H34: 24.47 | I34: 2 | J34: =IF(ISNUMBER(G34),IF(ABS(G34-H34)<=0.5*10^(-I34)+1E-9,"matches","MISMATCH"),"pending") | M34: nested-forecast | persistence 60
A35: C-NS-05 | B35: Ridge on CGM only chosen in 4 of 5 folds | C35: README.md (Results at a glance); reports/evidence_manifest.md; Deck s11 | D35: Participant-held-out internal (14 CGMacros people, each held out once; previously inspected) | E35: supported | F35: nest.ridge_folds | G35: =IF(AND(ISNUMBER(Sources!$C$221)),Sources!$C$221,"unavailable") | H35: 4 | I35: 0 | J35: =IF(ISNUMBER(G35),IF(ABS(G35-H35)<=0.5*10^(-I35)+1E-9,"matches","MISMATCH"),"pending") | M35: nested-forecast | folds choosing Ridge CGM-only
A36: C-EX-01 | B36: External 15-min LightGBM MAE 11.15 at 30 min | C36: README.md (Results at a glance); reports/evidence_manifest.md | D36: External ShanghaiT2DM, 98 people, CGM-only procedure (not the serving fusion model) | E36: supported | F36: ext.cand.mae30 | G36: =IF(AND(ISNUMBER(Sources!$C$201)),Sources!$C$201,"unavailable") | H36: 11.15 | I36: 2 | J36: =IF(ISNUMBER(G36),IF(ABS(G36-H36)<=0.5*10^(-I36)+1E-9,"matches","MISMATCH"),"pending") | K36: CGM only; tests the forecasting core, not the fusion | M36: external-15min | MAE 30
A37: C-EX-02 | B37: External 15-min LightGBM MAE 20.11 at 60 min | C37: README.md (Results at a glance); reports/evidence_manifest.md | D37: External ShanghaiT2DM, 98 people, CGM-only procedure (not the serving fusion model) | E37: supported | F37: ext.cand.mae60 | G37: =IF(AND(ISNUMBER(Sources!$C$213)),Sources!$C$213,"unavailable") | H37: 20.11 | I37: 2 | J37: =IF(ISNUMBER(G37),IF(ABS(G37-H37)<=0.5*10^(-I37)+1E-9,"matches","MISMATCH"),"pending") | K37: Source value 20.105 is an exact rounding tie at the source's own precision; stated 20.11 is one of its two valid roundings | M37: external-15min | MAE 60
A38: C-EX-03 | B38: External persistence 12.14 at 30 min | C38: README.md (Results at a glance); reports/evidence_manifest.md | D38: External ShanghaiT2DM, 98 people, CGM-only procedure (not the serving fusion model) | E38: supported | F38: ext.pers.mae30 | G38: =IF(AND(ISNUMBER(Sources!$C$202)),Sources!$C$202,"unavailable") | H38: 12.14 | I38: 2 | J38: =IF(ISNUMBER(G38),IF(ABS(G38-H38)<=0.5*10^(-I38)+1E-9,"matches","MISMATCH"),"pending") | K38: Source value 12.145 is an exact rounding tie at the source's own precision; stated 12.14 is one of its two valid roundings | M38: external-15min | persistence 30
A39: C-EX-04 | B39: External persistence 20.44 at 60 min | C39: README.md (Results at a glance); reports/evidence_manifest.md | D39: External ShanghaiT2DM, 98 people, CGM-only procedure (not the serving fusion model) | E39: supported | F39: ext.pers.mae60 | G39: =IF(AND(ISNUMBER(Sources!$C$214)),Sources!$C$214,"unavailable") | H39: 20.44 | I39: 2 | J39: =IF(ISNUMBER(G39),IF(ABS(G39-H39)<=0.5*10^(-I39)+1E-9,"matches","MISMATCH"),"pending") | M39: external-15min | persistence 60
A40: C-EX-05 | B40: External 60-minute difference is inconclusive (95 % CI upper bound above 0) | C40: README.md (Results at a glance); reports/evidence_manifest.md | D40: External ShanghaiT2DM, 98 people, CGM-only procedure (not the serving fusion model) | E40: supported | F40: ext.cmp.hi60; ext.cmp.lo60; ext.cmp.hi60 | G40: =IF(AND(ISNUMBER(Sources!$C$217)),Sources!$C$217,"unavailable") | H40: — | J40: see limitation | K40: Interval crosses zero | M40: external-15min | 60-minute difference
A41: C-PF-01 | B41: Profile minus no profile (held out) +0.34 mg/dL at 30 min | C41: README.md (Results at a glance); reports/evidence_manifest.md; README §7 | D41: Participant-held-out internal (14 CGMacros people, each held out once; previously inspected) | E41: negative-result | F41: nest.prof.d30 | G41: =IF(AND(ISNUMBER(Sources!$C$198)),Sources!$C$198,"unavailable") | H41: 0.34 | I41: 2 | J41: =IF(ISNUMBER(G41),IF(ABS(G41-H41)<=0.5*10^(-I41)+1E-9,"matches","MISMATCH"),"pending") | K41: CI [−0.28, +0.89] crosses zero: no reliable benefit; Source value 0.335 is an exact rounding tie at the source's own precision; stated 0.34 is one of its two valid roundings | M41: profile-ablation-nested | profile minus no profile, 30 min
...

Sheet Sources
A1: Sources — every source value stored once, at full precision | F1: ← About / navigation
A2: Value column is the only place a source number is typed by the builder; every other sheet references it. 'unavailable' = the file is not on this installation (never 0).
A4: Value ID | B4: Description | C4: Value | D4: Unit | E4: Source ID | F4: Repository path | G4: Locator (JSON pointer / field) | H4: Source date | I4: Source SHA-256 | J4: Protocol / revision identity | K4: Publication status
A5: fus.pers.mae30 | B5: Serving test (final test segment): Persistence (last reading), 30 min, mae (macro over participants) | C5: 14.836601 | D5: mg/dL | E5: fusion | F5: artifacts/experiments/gt-primary-2026-10-13-fusion/metrics.json | G5: /forecast_results[label=persistence:cgm-only-v1&personalization=off&split=test&horizon=30]/mae | H5: 2026-10-13T08:02:25+00:00 | I5: ec8d2e7aedb517e73fdb75284a8dea24bdb8de4b4f98257c6186d2cea56152d9 | J5: protocol configs/experiments/gt-primary-2026-10-13-fusion.yaml (first commit b60d149 2026-10-13T13:32:50+05:30) | K5: local / reproducible-only (git-ignored)
A6: fus.pers.rmse30 | B6: Serving test: Persistence (last reading), 30 min, rmse | C6: 22.083959 | D6: mg/dL | E6: fusion | F6: artifacts/experiments/gt-primary-2026-10-13-fusion/metrics.json | G6: /forecast_results[label=persistence:cgm-only-v1&personalization=off&split=test&horizon=30]/rmse | H6: 2026-10-13T08:02:25+00:00 | I6: ec8d2e7aedb517e73fdb75284a8dea24bdb8de4b4f98257c6186d2cea56152d9 | J6: protocol configs/experiments/gt-primary-2026-10-13-fusion.yaml (first commit b60d149 2026-10-13T13:32:50+05:30) | K6: local / reproducible-only (git-ignored)
A7: fus.pers.mae60 | B7: Serving test (final test segment): Persistence (last reading), 60 min, mae (macro over participants) | C7: 23.225387 | D7: mg/dL | E7: fusion | F7: artifacts/experiments/gt-primary-2026-10-13-fusion/metrics.json | G7: /forecast_results[label=persistence:cgm-only-v1&personalization=off&split=test&horizon=60]/mae | H7: 2026-10-13T08:02:25+00:00 | I7: ec8d2e7aedb517e73fdb75284a8dea24bdb8de4b4f98257c6186d2cea56152d9 | J7: protocol configs/experiments/gt-primary-2026-10-13-fusion.yaml (first commit b60d149 2026-10-13T13:32:50+05:30) | K7: local / reproducible-only (git-ignored)
A8: fus.pers.rmse60 | B8: Serving test: Persistence (last reading), 60 min, rmse | C8: 33.558213 | D8: mg/dL | E8: fusion | F8: artifacts/experiments/gt-primary-2026-10-13-fusion/metrics.json | G8: /forecast_results[label=persistence:cgm-only-v1&personalization=off&split=test&horizon=60]/rmse | H8: 2026-10-13T08:02:25+00:00 | I8: ec8d2e7aedb517e73fdb75284a8dea24bdb8de4b4f98257c6186d2cea56152d9 | J8: protocol configs/experiments/gt-primary-2026-10-13-fusion.yaml (first commit b60d149 2026-10-13T13:32:50+05:30) | K8: local / reproducible-only (git-ignored)
A9: fus.trend.mae30 | B9: Serving test (final test segment): Linear trend, 30 min, mae (macro over participants) | C9: 14.031539 | D9: mg/dL | E9: fusion | F9: artifacts/experiments/gt-primary-2026-10-13-fusion/metrics.json | G9: /forecast_results[label=linear_trend:cgm-only-v1&personalization=off&split=test&horizon=30]/mae | H9: 2026-10-13T08:02:25+00:00 | I9: ec8d2e7aedb517e73fdb75284a8dea24bdb8de4b4f98257c6186d2cea56152d9 | J9: protocol configs/experiments/gt-primary-2026-10-13-fusion.yaml (first commit b60d149 2026-10-13T13:32:50+05:30) | K9: local / reproducible-only (git-ignored)
A10: fus.trend.rmse30 | B10: Serving test: Linear trend, 30 min, rmse | C10: 21.034836 | D10: mg/dL | E10: fusion | F10: artifacts/experiments/gt-primary-2026-10-13-fusion/metrics.json | G10: /forecast_results[label=linear_trend:cgm-only-v1&personalization=off&split=test&horizon=30]/rmse | H10: 2026-10-13T08:02:25+00:00 | I10: ec8d2e7aedb517e73fdb75284a8dea24bdb8de4b4f98257c6186d2cea56152d9 | J10: protocol configs/experiments/gt-primary-2026-10-13-fusion.yaml (first commit b60d149 2026-10-13T13:32:50+05:30) | K10: local / reproducible-only (git-ignored)
A11: fus.trend.mae60 | B11: Serving test (final test segment): Linear trend, 60 min, mae (macro over participants) | C11: 23.231287 | D11: mg/dL | E11: fusion | F11: artifacts/experiments/gt-primary-2026-10-13-fusion/metrics.json | G11: /forecast_results[label=linear_trend:cgm-only-v1&personalization=off&split=test&horizon=60]/mae | H11: 2026-10-13T08:02:25+00:00 | I11: ec8d2e7aedb517e73fdb75284a8dea24bdb8de4b4f98257c6186d2cea56152d9 | J11: protocol configs/experiments/gt-primary-2026-10-13-fusion.yaml (first commit b60d149 2026-10-13T13:32:50+05:30) | K11: local / reproducible-only (git-ignored)
A12: fus.trend.rmse60 | B12: Serving test: Linear trend, 60 min, rmse | C12: 33.959262 | D12: mg/dL | E12: fusion | F12: artifacts/experiments/gt-primary-2026-10-13-fusion/metrics.json | G12: /forecast_results[label=linear_trend:cgm-only-v1&personalization=off&split=test&horizon=60]/rmse | H12: 2026-10-13T08:02:25+00:00 | I12: ec8d2e7aedb517e73fdb75284a8dea24bdb8de4b4f98257c6186d2cea56152d9 | J12: protocol configs/experiments/gt-primary-2026-10-13-fusion.yaml (first commit b60d149 2026-10-13T13:32:50+05:30) | K12: local / reproducible-only (git-ignored)
A13: fus.ridgep.mae30 | B13: Serving test (final test segment): Ridge, dynamic + profile, 30 min, mae (macro over participants) | C13: 14.606677 | D13: mg/dL | E13: fusion | F13: artifacts/experiments/gt-primary-2026-10-13-fusion/metrics.json | G13: /forecast_results[label=ridge:dyn-prof-v2&personalization=off&split=test&horizon=30]/mae | H13: 2026-10-13T08:02:25+00:00 | I13: ec8d2e7aedb517e73fdb75284a8dea24bdb8de4b4f98257c6186d2cea56152d9 | J13: protocol configs/experiments/gt-primary-2026-10-13-fusion.yaml (first commit b60d149 2026-10-13T13:32:50+05:30) | K13: local / reproducible-only (git-ignored)
A14: fus.ridgep.rmse30 | B14: Serving test: Ridge, dynamic + profile, 30 min, rmse | C14: 21.248721 | D14: mg/dL | E14: fusion | F14: artifacts/experiments/gt-primary-2026-10-13-fusion/metrics.json | G14: /forecast_results[label=ridge:dyn-prof-v2&personalization=off&split=test&horizon=30]/rmse | H14: 2026-10-13T08:02:25+00:00 | I14: ec8d2e7aedb517e73fdb75284a8dea24bdb8de4b4f98257c6186d2cea56152d9 | J14: protocol configs/experiments/gt-primary-2026-10-13-fusion.yaml (first commit b60d149 2026-10-13T13:32:50+05:30) | K14: local / reproducible-only (git-ignored)
A15: fus.ridgep.mae60 | B15: Serving test (final test segment): Ridge, dynamic + profile, 60 min, mae (macro over participants) | C15: 22.964396 | D15: mg/dL | E15: fusion | F15: artifacts/experiments/gt-primary-2026-10-13-fusion/metrics.json | G15: /forecast_results[label=ridge:dyn-prof-v2&personalization=off&split=test&horizon=60]/mae | H15: 2026-10-13T08:02:25+00:00 | I15: ec8d2e7aedb517e73fdb75284a8dea24bdb8de4b4f98257c6186d2cea56152d9 | J15: protocol configs/experiments/gt-primary-2026-10-13-fusion.yaml (first commit b60d149 2026-10-13T13:32:50+05:30) | K15: local / reproducible-only (git-ignored)
A16: fus.ridgep.rmse60 | B16: Serving test: Ridge, dynamic + profile, 60 min, rmse | C16: 31.831124 | D16: mg/dL | E16: fusion | F16: artifacts/experiments/gt-primary-2026-10-13-fusion/metrics.json | G16: /forecast_results[label=ridge:dyn-prof-v2&personalization=off&split=test&horizon=60]/rmse | H16: 2026-10-13T08:02:25+00:00 | I16: ec8d2e7aedb517e73fdb75284a8dea24bdb8de4b4f98257c6186d2cea56152d9 | J16: protocol configs/experiments/gt-primary-2026-10-13-fusion.yaml (first commit b60d149 2026-10-13T13:32:50+05:30) | K16: local / reproducible-only (git-ignored)
... A72: fus.ev.threshold | B72: Serving 60-min warning, final test: warning margin (score = max forecast − 180) | C72: -10 | D72: mg/dL | E72: fusion | F72: artifacts/experiments/gt-primary-2026-10-13-fusion/metrics.json | G72: /events[model=lightgbm:dyn-prof-v2 (adaptive)&split=test&horizon=60]/threshold | H72: 2026-10-13T08:02:25+00:00 | I72: ec8d2e7aedb517e73fdb75284a8dea24bdb8de4b4f98257c6186d2cea56152d9 | J72: protocol configs/experiments/gt-primary-2026-10-13-fusion.yaml (first commit b60d149 2026-10-13T13:32:50+05:30) | K72: local / reproducible-only (git-ignored)
A73: fus.ev.time_base | B73: Serving 60-min warning, final test: time-base definition of the day denominators | C73: approximate: number of forecast-issued origins x 5-minute native cadence | D73: text | E73: fusion | F73: artifacts/experiments/gt-primary-2026-10-13-fusion/metrics.json | G73: /events[model=lightgbm:dyn-prof-v2 (adaptive)&split=test&horizon=60]/time_base | H73: 2026-10-13T08:02:25+00:00 | I73: ec8d2e7aedb517e73fdb75284a8dea24bdb8de4b4f98257c6186d2cea56152d9 | J73: protocol configs/experiments/gt-primary-2026-10-13-fusion.yaml (first commit b60d149 2026-10-13T13:32:50+05:30) | K73: local / reproducible-only (git-ignored)
A74: fus.ev.iqr_lo | B74: Qualified lead IQR lower (detected onsets) | C74: 10 | D74: min | E74: fusion | F74: artifacts/experiments/gt-primary-2026-10-13-fusion/metrics.json | G74: /events[model=lightgbm:dyn-prof-v2 (adaptive)&split=test&horizon=60]/qualified_lead_iqr[0] | H74: 2026-10-13T08:02:25+00:00 | I74: ec8d2e7aedb517e73fdb75284a8dea24bdb8de4b4f98257c6186d2cea56152d9 | J74: protocol configs/experiments/gt-primary-2026-10-13-fusion.yaml (first commit b60d149 2026-10-13T13:32:50+05:30) | K74: local / reproducible-only (git-ignored)
A75: fus.ev.iqr_hi | B75: Qualified lead IQR upper (detected onsets) | C75: 55 | D75: min | E75: fusion | F75: artifacts/experiments/gt-primary-2026-10-13-fusion/metrics.json | G75: /events[model=lightgbm:dyn-prof-v2 (adaptive)&split=test&horizon=60]/qualified_lead_iqr[1] | H75: 2026-10-13T08:02:25+00:00 | I75: ec8d2e7aedb517e73fdb75284a8dea24bdb8de4b4f98257c6186d2cea56152d9 | J75: protocol configs/experiments/gt-primary-2026-10-13-fusion.yaml (first commit b60d149 2026-10-13T13:32:50+05:30) | K75: local / reproducible-only (git-ignored)
A76: fus.pev.detected_onsets | B76: Persistence 60-min warning (fires at 150 mg/dL), final test: detected_onsets | C76: 63 | D76: count | E76: fusion | F76: artifacts/experiments/gt-primary-2026-10-13-fusion/metrics.json | G76: /events[model=persistence&split=test&horizon=60]/detected_onsets | H76: 2026-10-13T08:02:25+00:00 | I76: ec8d2e7aedb517e73fdb75284a8dea24bdb8de4b4f98257c6186d2cea56152d9 | J76: protocol configs/experiments/gt-primary-2026-10-13-fusion.yaml (first commit b60d149 2026-10-13T13:32:50+05:30) | K76: local / reproducible-only (git-ignored)
A77: fus.pev.false_alarm_episodes | B77: Persistence 60-min warning (fires at 150 mg/dL), final test: false_alarm_episodes | C77: 70 | D77: count | E77: fusion | F77: artifacts/experiments/gt-primary-2026-10-13-fusion/metrics.json | G77: /events[model=persistence&split=test&horizon=60]/false_alarm_episodes | H77: 2026-10-13T08:02:25+00:00 | I77: ec8d2e7aedb517e73fdb75284a8dea24bdb8de4b4f98257c6186d2cea56152d9 | J77: protocol configs/experiments/gt-primary-2026-10-13-fusion.yaml (first commit b60d149 2026-10-13T13:32:50+05:30) | K77: local / reproducible-only (git-ignored)
A78: fus.pev.false_alarms_per_observed_patient_day | B78: Persistence 60-min warning (fires at 150 mg/dL), final test: false_alarms_per_observed_patient_day | C78: 2.611399 | D78: count | E78: fusion | F78: artifacts/experiments/gt-primary-2026-10-13-fusion/metrics.json | G78: /events[model=persistence&split=test&horizon=60]/false_alarms_per_observed_patient_day | H78: 2026-10-13T08:02:25+00:00 | I78: ec8d2e7aedb517e73fdb75284a8dea24bdb8de4b4f98257c6186d2cea56152d9 | J78: protocol configs/experiments/gt-primary-2026-10-13-fusion.yaml (first commit b60d149 2026-10-13T13:32:50+05:30) | K78: local / reproducible-only (git-ignored)
A79: fus.iv.coverage30 | B79: Served 80 % range, final test, 30 min: coverage | C79: 0.74204442 | D79: share | E79: fusion | F79: artifacts/experiments/gt-primary-2026-10-13-fusion/metrics.json | G79: /intervals[label=lightgbm:dyn-prof-v2&personalization=adaptive&split=test&horizon=30]/coverage | H79: 2026-10-13T08:02:25+00:00 | I79: ec8d2e7aedb517e73fdb75284a8dea24bdb8de4b4f98257c6186d2cea56152d9 | J79: protocol configs/experiments/gt-primary-2026-10-13-fusion.yaml (first commit b60d149 2026-10-13T13:32:50+05:30) | K79: local / reproducible-only (git-ignored)
A80: fus.iv.width30 | B80: Served 80 % range, final test, 30 min: width | C80: 33.423399 | D80: mg/dL | E80: fusion | F80: artifacts/experiments/gt-primary-2026-10-13-fusion/metrics.json | G80: /intervals[label=lightgbm:dyn-prof-v2&personalization=adaptive&split=test&horizon=30]/width | H80: 2026-10-13T08:02:25+00:00 | I80: ec8d2e7aedb517e73fdb75284a8dea24bdb8de4b4f98257c6186d2cea56152d9 | J80: protocol configs/experiments/gt-primary-2026-10-13-fusion.yaml (first commit b60d149 2026-10-13T13:32:50+05:30) | K80: local / reproducible-only (git-ignored)
A81: fus.iv.q30 | B81: Served 80 % range, final test, 30 min: q | C81: 16.7117 | D81: mg/dL | E81: fusion | F81: artifacts/experiments/gt-primary-2026-10-13-fusion/metrics.json | G81: /intervals[label=lightgbm:dyn-prof-v2&personalization=adaptive&split=test&horizon=30]/q | H81: 2026-10-13T08:02:25+00:00 | I81: ec8d2e7aedb517e73fdb75284a8dea24bdb8de4b4f98257c6186d2cea56152d9 | J81: protocol configs/experiments/gt-primary-2026-10-13-fusion.yaml (first commit b60d149 2026-10-13T13:32:50+05:30) | K81: local / reproducible-only (git-ignored)
A82: fus.iv.per_patient_min30 | B82: Served 80 % range, final test, 30 min: per_patient_min | C82: 0.60263653 | D82: share | E82: fusion | F82: artifacts/experiments/gt-primary-2026-10-13-fusion/metrics.json | G82: /intervals[label=lightgbm:dyn-prof-v2&personalization=adaptive&split=test&horizon=30]/per_patient_min | H82: 2026-10-13T08:02:25+00:00 | I82: ec8d2e7aedb517e73fdb75284a8dea24bdb8de4b4f98257c6186d2cea56152d9 | J82: protocol configs/experiments/gt-primary-2026-10-13-fusion.yaml (first commit b60d149 2026-10-13T13:32:50+05:30) | K82: local / reproducible-only (git-ignored)
A83: fus.iv.per_patient_max30 | B83: Served 80 % range, final test, 30 min: per_patient_max | C83: 0.82310469 | D83: share | E83: fusion | F83: artifacts/experiments/gt-primary-2026-10-13-fusion/metrics.json | G83: /intervals[label=lightgbm:dyn-prof-v2&personalization=adaptive&split=test&horizon=30]/per_patient_max | H83: 2026-10-13T08:02:25+00:00 | I83: ec8d2e7aedb517e73fdb75284a8dea24bdb8de4b4f98257c6186d2cea56152d9 | J83: protocol configs/experiments/gt-primary-2026-10-13-fusion.yaml (first commit b60d149 2026-10-13T13:32:50+05:30) | K83: local / reproducible-only (git-ignored)
A84: fus.iv.n30 | B84: Served 80 % range, final test, 30 min: n | C84: 7699 | D84: origins | E84: fusion | F84: artifacts/experiments/gt-primary-2026-10-13-fusion/metrics.json | G84: /intervals[label=lightgbm:dyn-prof-v2&personalization=adaptive&split=test&horizon=30]/n | H84: 2026-10-13T08:02:25+00:00 | I84: ec8d2e7aedb517e73fdb75284a8dea24bdb8de4b4f98257c6186d2cea56152d9 | J84: protocol configs/experiments/gt-primary-2026-10-13-fusion.yaml (first commit b60d149 2026-10-13T13:32:50+05:30) | K84: local / reproducible-only (git-ignored)
A85: fus.iv.coverage60 | B85: Served 80 % range, final test, 60 min: coverage | C85: 0.73979194 | D85: share | E85: fusion | F85: artifacts/experiments/gt-primary-2026-10-13-fusion/metrics.json | G85: /intervals[label=lightgbm:dyn-prof-v2&personalization=adaptive&split=test&horizon=60]/coverage | H85: 2026-10-13T08:02:25+00:00 | I85: ec8d2e7aedb517e73fdb75284a8dea24bdb8de4b4f98257c6186d2cea56152d9 | J85: protocol configs/experiments/gt-primary-2026-10-13-fusion.yaml (first commit b60d149 2026-10-13T13:32:50+05:30) | K85: local / reproducible-only (git-ignored)
... A117: fus.sens.meal60 | B117: Optimistic meal-logging sensitivity (not eligible for serving), test, 60 min | C117: 19.073062 | D117: mg/dL | E117: fusion | F117: artifacts/experiments/gt-primary-2026-10-13-fusion/metrics.json | G117: /sensitivity[experiment=optimistic meal logging&split=test&horizon=60]/mae | H117: 2026-10-13T08:02:25+00:00 | I117: ec8d2e7aedb517e73fdb75284a8dea24bdb8de4b4f98257c6186d2cea56152d9 | J117: protocol configs/experiments/gt-primary-2026-10-13-fusion.yaml (first commit b60d149 2026-10-13T13:32:50+05:30) | K117: local / reproducible-only (git-ignored)
A118: fus.model_version | B118: Model version evaluated | C118: lightgbm.dyn-prof-v2.gt-primary-2026-10-13-fusion | D118: text | E118: fusion | F118: artifacts/experiments/gt-primary-2026-10-13-fusion/metrics.json | G118: /model_version | H118: 2026-10-13T08:02:25+00:00 | I118: ec8d2e7aedb517e73fdb75284a8dea24bdb8de4b4f98257c6186d2cea56152d9 | J118: protocol configs/experiments/gt-primary-2026-10-13-fusion.yaml (first commit b60d149 2026-10-13T13:32:50+05:30) | K118: local / reproducible-only (git-ignored)
A119: fus.created_at | B119: Experiment run time | C119: 46308.335 | D119: UTC | E119: fusion | F119: artifacts/experiments/gt-primary-2026-10-13-fusion/metrics.json | G119: /created_at | H119: 2026-10-13T08:02:25+00:00 | I119: ec8d2e7aedb517e73fdb75284a8dea24bdb8de4b4f98257c6186d2cea56152d9 | J119: protocol configs/experiments/gt-primary-2026-10-13-fusion.yaml (first commit b60d149 2026-10-13T13:32:50+05:30) | K119: local / reproducible-only (git-ignored)
A120: fus.selection_rule | B120: Declared selection rule | C120: Lowest equal-weight mean of per-patient MAE across the 30- and 60-minute horizons on the validation-selection segment, population model without patient adaptation. | D120: text | E120: fusion | F120: artifacts/experiments/gt-primary-2026-10-13-fusion/metrics.json | G120: /selection/rule | H120: 2026-10-13T08:02:25+00:00 | I120: ec8d2e7aedb517e73fdb75284a8dea24bdb8de4b4f98257c6186d2cea56152d9 | J120: protocol configs/experiments/gt-primary-2026-10-13-fusion.yaml (first commit b60d149 2026-10-13T13:32:50+05:30) | K120: local / reproducible-only (git-ignored)
A121: fus.better30 | B121: Serving test: participants with lower serving error than persistence, 30 min (derived count) | C121: 14 | D121: people | E121: fusion | F121: artifacts/experiments/gt-primary-2026-10-13-fusion/metrics.json | G121: /per_patient_test (count of people with serving MAE < persistence MAE, 30 min) | H121: 2026-10-13T08:02:25+00:00 | I121: ec8d2e7aedb517e73fdb75284a8dea24bdb8de4b4f98257c6186d2cea56152d9 | J121: protocol configs/experiments/gt-primary-2026-10-13-fusion.yaml (first commit b60d149 2026-10-13T13:32:50+05:30) | K121: local / reproducible-only (git-ignored)
A122: fus.better60 | B122: Serving test: participants with lower serving error than persistence, 60 min (derived count) | C122: 13 | D122: people | E122: fusion | F122: artifacts/experiments/gt-primary-2026-10-13-fusion/metrics.json | G122: /per_patient_test (count of people with serving MAE < persistence MAE, 60 min) | H122: 2026-10-13T08:02:25+00:00 | I122: ec8d2e7aedb517e73fdb75284a8dea24bdb8de4b4f98257c6186d2cea56152d9 | J122: protocol configs/experiments/gt-primary-2026-10-13-fusion.yaml (first commit b60d149 2026-10-13T13:32:50+05:30) | K122: local / reproducible-only (git-ignored)
A123: wu.onsets | B123: Serving 60-min warning, final test: eligible onsets (denominator of every notice share) | C123: 64 | D123: onsets | E123: fusion_pred | F123: artifacts/experiments/gt-primary-2026-10-13-fusion/predictions.parquet | G123: scripts/warning_utility.py demo row (WT.demo, key=demo) → onsets | H123: 2026-10-13T08:02:25+00:00 (file time) | I123: 1a5a7164fd8d17f36a4248a5a9f30f2dfee53b30b010ca62fab30df8c77b1778 | J123: protocol configs/experiments/gt-primary-2026-10-13-fusion.yaml (first commit b60d149 2026-10-13T13:32:50+05:30) | K123: local / reproducible-only (git-ignored)
A124: wu.detected | B124: Serving 60-min warning, final test: detected onsets | C124: 61 | D124: onsets | E124: fusion_pred | F124: artifacts/experiments/gt-primary-2026-10-13-fusion/predictions.parquet | G124: scripts/warning_utility.py demo row (WT.demo, key=demo) → detected | H124: 2026-10-13T08:02:25+00:00 (file time) | I124: 1a5a7164fd8d17f36a4248a5a9f30f2dfee53b30b010ca62fab30df8c77b1778 | J124: protocol configs/experiments/gt-primary-2026-10-13-fusion.yaml (first commit b60d149 2026-10-13T13:32:50+05:30) | K124: local / reproducible-only (git-ignored)
A125: wu.ge15 | B125: Serving 60-min warning, final test: onsets warned ≥ 15 min ahead (qualified lead) | C125: 43 | D125: onsets | E125: fusion_pred | F125: artifacts/experiments/gt-primary-2026-10-13-fusion/predictions.parquet | G125: scripts/warning_utility.py demo row (WT.demo, key=demo) → ge15 | H125: 2026-10-13T08:02:25+00:00 (file time) | I125: 1a5a7164fd8d17f36a4248a5a9f30f2dfee53b30b010ca62fab30df8c77b1778 | J125: protocol configs/experiments/gt-primary-2026-10-13-fusion.yaml (first commit b60d149 2026-10-13T13:32:50+05:30) | K125: local / reproducible-only (git-ignored)
A126: wu.ge30 | B126: Serving 60-min warning, final test: onsets warned ≥ 30 min ahead (qualified lead) | C126: 31 | D126: onsets | E126: fusion_pred | F126: artifacts/experiments/gt-primary-2026-10-13-fusion/predictions.parquet | G126: scripts/warning_utility.py demo row (WT.demo, key=demo) → ge30 | H126: 2026-10-13T08:02:25+00:00 (file time) | I126: 1a5a7164fd8d17f36a4248a5a9f30f2dfee53b30b010ca62fab30df8c77b1778 | J126: protocol configs/experiments/gt-primary-2026-10-13-fusion.yaml (first commit b60d149 2026-10-13T13:32:50+05:30) | K126: local / reproducible-only (git-ignored)
A127: wu.ge60 | B127: Serving 60-min warning, final test: onsets warned ≥ 60 min ahead (qualified lead) | C127: 13 | D127: onsets | E127: fusion_pred | F127: artifacts/experiments/gt-primary-2026-10-13-fusion/predictions.parquet | G127: scripts/warning_utility.py demo row (WT.demo, key=demo) → ge60 | H127: 2026-10-13T08:02:25+00:00 (file time) | I127: 1a5a7164fd8d17f36a4248a5a9f30f2dfee53b30b010ca62fab30df8c77b1778 | J127: protocol configs/experiments/gt-primary-2026-10-13-fusion.yaml (first commit b60d149 2026-10-13T13:32:50+05:30) | K127: local / reproducible-only (git-ignored)
...

Sheet Cohorts
A1: Cohorts — who each result counts | F1: ← About / navigation
A2: Separate evaluation groups; never compare rows across groups.
A4: Evaluation group | B4: Dataset / version | C4: Participants | D4: What the participant count means | E4: Cadence | F4: Split roles | G4: Horizon (min) | H4: Origins / forecasts | I4: Hours | J4: Onsets | K4: Inspected / unseen status | L4: Opening disclosure | M4: Model scope | N4: Source IDs
A5: Serving test (final test segment) | B5: CGMacros 1.0.0 | C5: =IF(AND(ISNUMBER(Sources!$C$115)),Sources!$C$115,"unavailable") | D5: Type 2 group (HbA1c > 6.4 %), same people as training | E5: 5 min | F5: Chronological 60/10/10/20 within each person: training / selection / calibration / test, purge gaps | G5: 30, 60 | H5: =IF(AND(ISNUMBER(Sources!$C$109)),Sources!$C$109,"unavailable") | I5: =IF(AND(ISNUMBER(Sources!$C$111)),Sources!$C$111,"unavailable") | J5: =IF(AND(ISNUMBER(Sources!$C$114)),Sources!$C$114,"unavailable") | K5: Inspected: the v1/v2 test segment was read before the fusion constraint was declared (retrospective) | L5: Later recordings of the same 14 people — never 'unseen patients' | M5: Serving fusion LightGBM + correction | N5: fus.participants; fus.seg.test.*
A6: Serving model selection (validation segment) | B6: CGMacros 1.0.0 | C6: =IF(AND(ISNUMBER(Sources!$C$115)),Sources!$C$115,"unavailable") | D6: Same 14 people | E6: 5 min | F6: Validation segment used for model, threshold and adaptation choice | G6: 30, 60 | H6: =IF(AND(ISNUMBER(Sources!$C$97)),Sources!$C$97,"unavailable") | I6: =IF(AND(ISNUMBER(Sources!$C$99)),Sources!$C$99,"unavailable") | J6: =IF(AND(ISNUMBER(Sources!$C$102)),Sources!$C$102,"unavailable") | K6: Used for selection | L6: — | M6: Serving candidates | N6: fus.seg.validation.*
A7: Serving calibration segment | B7: CGMacros 1.0.0 | C7: =IF(AND(ISNUMBER(Sources!$C$115)),Sources!$C$115,"unavailable") | D7: Same 14 people | E7: 5 min | F7: Split-conformal range calibration | G7: 30, 60 | H7: =IF(AND(ISNUMBER(Sources!$C$103)),Sources!$C$103,"unavailable") | I7: =IF(AND(ISNUMBER(Sources!$C$105)),Sources!$C$105,"unavailable") | J7: =IF(AND(ISNUMBER(Sources!$C$108)),Sources!$C$108,"unavailable") | K7: Used for calibration | L7: — | M7: Serving ranges | N7: fus.seg.calibration.*
A8: Excluded CGMacros participants | B8: CGMacros 1.0.0 | C8: =IF(AND(ISNUMBER(Sources!$C$116)),Sources!$C$116,"unavailable") | D8: Pre-diabetes or no diabetes; replay only | E8: 5 min | F8: Never used in training or evaluation | G8: — | H8: — | I8: — | J8: — | K8: Not evaluated | L8: — | M8: Replay only | N8: fus.excluded; inv.cgm
A9: Participant-held-out internal (D-032 nested; D-043…D-053 reuse the folds) | B9: CGMacros 1.0.0 | C9: =IF(AND(ISNUMBER(Sources!$C$458)),Sources!$C$458,"unavailable") | D9: Each of the 14 people held out entirely once (5 outer folds) | E9: 5 min | F9: Outer folds assess; inner folds select; calibration people for ranges | G9: 30, 60 (120 in D-043) | H9: — | I9: — | J9: — | K9: Previously inspected people: internal validation, not an untouched cohort | L9: Each study opens its outer folds once behind a lock file | M9: Research procedures (not served) | N9: inv.cgm_eval; nest.*
A10: External (D-032 first opening; D-045 second opening) | B10: ShanghaiT2DM, figshare 21600933 v5 | C10: =IF(AND(ISNUMBER(Sources!$C$459)),Sources!$C$459,"unavailable") | D10: Type 2 people imported (100) with usable recordings | E10: 15 min | F10: Assessment only; nothing chosen on this cohort | G10: 30, 60, 120 | H10: — | I10: — | J10: — | K10: Reserved external cohort | L10: Opened twice (D-032 30/60; D-045 120) | M10: CGM-only 15-min LightGBM — not the fusion model | N10: inv.sh; inv.sh_eval
A11: Foundation baseline (D-054) | B11: CGMacros 1.0.0 | C11: =IF(AND(ISNUMBER(Sources!$C$115)),Sources!$C$115,"unavailable") | D11: All 14 Type 2 people, all eligible origins | E11: 5 min | F11: No training (zero-shot) | G11: 30, 60 | H11: =IF(AND(ISNUMBER(Sources!$C$455)),Sources!$C$455,"unavailable") | I11: — | J11: — | K11: Previously inspected people | L11: — | M11: Chronos-Bolt-Tiny, CGM only | N11: fd.origins
A12: Synthetic demonstration | B12: Fictional synthetic participants | C12: — | D12: Fictional; labelled synthetic everywhere | E12: 5 min | F12: — | G12: 30, 60 | H12: — | I12: — | J12: — | K12: Never evidence of performance | L12: — | M12: synthetic-demo.lightgbm.dyn-v2.v1 | N12: reg.synthetic; reg.synthetic_fitted

Sheet Forecasts
A1: Forecasts — errors by evaluation, model and horizon | F1: ← About / navigation
A2: MAE = mean absolute error, macro (equal weight per participant). Difference = candidate − persistence on the same origins (negative = lower error). Saved paired differences and CIs are participant-bootstrap values from the artifacts.
A4: Evaluation group | B4: Model / procedure | C4: Horizon (min) | D4: Aggregation | E4: MAE (mg/dL) | F4: Persistence MAE, same origins | G4: Candidate − persistence (formula) | H4: Relative change % (formula) | I4: RMSE (mg/dL) | J4: Saved paired diff | K4: CI 95 % low | L4: CI 95 % high | M4: Note | N4: Source IDs
A5: Serving model, final test segment (later recordings of the same 14 people; retrospective, inspected) | B5: Fusion LightGBM + correction (SERVING) | C5: 30 | D5: macro per participant | E5: =IF(AND(ISNUMBER(Sources!$C$25)),Sources!$C$25,"unavailable") | F5: =IF(AND(ISNUMBER(Sources!$C$5)),Sources!$C$5,"unavailable") | G5: =IF(AND(ISNUMBER(E5),ISNUMBER(F5)),E5-F5,"unavailable") | H5: =IF(AND(ISNUMBER(E5),ISNUMBER(F5)),(E5-F5)/F5*100,"unavailable") | I5: =IF(AND(ISNUMBER(Sources!$C$26)),Sources!$C$26,"unavailable") | J5: =IF(AND(ISNUMBER(Sources!$C$37)),Sources!$C$37,"unavailable") | K5: =IF(AND(ISNUMBER(Sources!$C$38)),Sources!$C$38,"unavailable") | L5: =IF(AND(ISNUMBER(Sources!$C$39)),Sources!$C$39,"unavailable") | M5: Retrospective; same 14 people as training | N5: fus.serv.mae30; fus.pers.mae30; fus.serv.rmse30; fus.cmp.sp.d30; fus.cmp.sp.lo30; fus.cmp.sp.hi30
A6: Serving model, final test segment (later recordings of the same 14 people; retrospective, inspected) | B6: Fusion LightGBM + correction (SERVING) | C6: 60 | D6: macro per participant | E6: =IF(AND(ISNUMBER(Sources!$C$29)),Sources!$C$29,"unavailable") | F6: =IF(AND(ISNUMBER(Sources!$C$7)),Sources!$C$7,"unavailable") | G6: =IF(AND(ISNUMBER(E6),ISNUMBER(F6)),E6-F6,"unavailable") | H6: =IF(AND(ISNUMBER(E6),ISNUMBER(F6)),(E6-F6)/F6*100,"unavailable") | I6: =IF(AND(ISNUMBER(Sources!$C$30)),Sources!$C$30,"unavailable") | J6: =IF(AND(ISNUMBER(Sources!$C$40)),Sources!$C$40,"unavailable") | K6: =IF(AND(ISNUMBER(Sources!$C$41)),Sources!$C$41,"unavailable") | L6: =IF(AND(ISNUMBER(Sources!$C$42)),Sources!$C$42,"unavailable") | M6: Retrospective; same 14 people as training | N6: fus.serv.mae60; fus.pers.mae60; fus.serv.rmse60; fus.cmp.sp.d60; fus.cmp.sp.lo60; fus.cmp.sp.hi60
A7: Serving model, final test segment (later recordings of the same 14 people; retrospective, inspected) | B7: CatBoost + profile + correction (not selected) | C7: 30 | D7: macro per participant | E7: =IF(AND(ISNUMBER(Sources!$C$33)),Sources!$C$33,"unavailable") | F7: =IF(AND(ISNUMBER(Sources!$C$5)),Sources!$C$5,"unavailable") | G7: =IF(AND(ISNUMBER(E7),ISNUMBER(F7)),E7-F7,"unavailable") | H7: =IF(AND(ISNUMBER(E7),ISNUMBER(F7)),(E7-F7)/F7*100,"unavailable") | I7: =IF(AND(ISNUMBER(Sources!$C$34)),Sources!$C$34,"unavailable") | J7: — | K7: — | L7: — | N7: fus.cbpa.mae30; fus.pers.mae30; fus.cbpa.rmse30
A8: Serving model, final test segment (later recordings of the same 14 people; retrospective, inspected) | B8: CatBoost + profile + correction (not selected) | C8: 60 | D8: macro per participant | E8: =IF(AND(ISNUMBER(Sources!$C$35)),Sources!$C$35,"unavailable") | F8: =IF(AND(ISNUMBER(Sources!$C$7)),Sources!$C$7,"unavailable") | G8: =IF(AND(ISNUMBER(E8),ISNUMBER(F8)),E8-F8,"unavailable") | H8: =IF(AND(ISNUMBER(E8),ISNUMBER(F8)),(E8-F8)/F8*100,"unavailable") | I8: =IF(AND(ISNUMBER(Sources!$C$36)),Sources!$C$36,"unavailable") | J8: — | K8: — | L8: — | N8: fus.cbpa.mae60; fus.pers.mae60; fus.cbpa.rmse60
A9: Serving model, final test segment (later recordings of the same 14 people; retrospective, inspected) | B9: LightGBM + profile, population | C9: 30 | D9: macro per participant | E9: =IF(AND(ISNUMBER(Sources!$C$21)),Sources!$C$21,"unavailable") | F9: =IF(AND(ISNUMBER(Sources!$C$5)),Sources!$C$5,"unavailable") | G9: =IF(AND(ISNUMBER(E9),ISNUMBER(F9)),E9-F9,"unavailable") | H9: =IF(AND(ISNUMBER(E9),ISNUMBER(F9)),(E9-F9)/F9*100,"unavailable") | I9: =IF(AND(ISNUMBER(Sources!$C$22)),Sources!$C$22,"unavailable") | J9: — | K9: — | L9: — | N9: fus.lgbp.mae30; fus.pers.mae30; fus.lgbp.rmse30
A10: Serving model, final test segment (later recordings of the same 14 people; retrospective, inspected) | B10: LightGBM + profile, population | C10: 60 | D10: macro per participant | E10: =IF(AND(ISNUMBER(Sources!$C$23)),Sources!$C$23,"unavailable") | F10: =IF(AND(ISNUMBER(Sources!$C$7)),Sources!$C$7,"unavailable") | G10: =IF(AND(ISNUMBER(E10),ISNUMBER(F10)),E10-F10,"unavailable") | H10: =IF(AND(ISNUMBER(E10),ISNUMBER(F10)),(E10-F10)/F10*100,"unavailable") | I10: =IF(AND(ISNUMBER(Sources!$C$24)),Sources!$C$24,"unavailable") | J10: — | K10: — | L10: — | N10: fus.lgbp.mae60; fus.pers.mae60; fus.lgbp.rmse60
A11: Serving model, final test segment (later recordings of the same 14 people; retrospective, inspected) | B11: LightGBM dynamic-only + correction (v2) | C11: 30 | D11: macro per participant | E11: =IF(AND(ISNUMBER(Sources!$C$17)),Sources!$C$17,"unavailable") | F11: =IF(AND(ISNUMBER(Sources!$C$5)),Sources!$C$5,"unavailable") | G11: =IF(AND(ISNUMBER(E11),ISNUMBER(F11)),E11-F11,"unavailable") | H11: =IF(AND(ISNUMBER(E11),ISNUMBER(F11)),(E11-F11)/F11*100,"unavailable") | I11: =IF(AND(ISNUMBER(Sources!$C$18)),Sources!$C$18,"unavailable") | J11: — | K11: — | L11: — | N11: fus.v2a.mae30; fus.pers.mae30; fus.v2a.rmse30
A12: Serving model, final test segment (later recordings of the same 14 people; retrospective, inspected) | B12: LightGBM dynamic-only + correction (v2) | C12: 60 | D12: macro per participant | E12: =IF(AND(ISNUMBER(Sources!$C$19)),Sources!$C$19,"unavailable") | F12: =IF(AND(ISNUMBER(Sources!$C$7)),Sources!$C$7,"unavailable") | G12: =IF(AND(ISNUMBER(E12),ISNUMBER(F12)),E12-F12,"unavailable") | H12: =IF(AND(ISNUMBER(E12),ISNUMBER(F12)),(E12-F12)/F12*100,"unavailable") | I12: =IF(AND(ISNUMBER(Sources!$C$20)),Sources!$C$20,"unavailable") | J12: — | K12: — | L12: — | N12: fus.v2a.mae60; fus.pers.mae60; fus.v2a.rmse60
A13: Serving model, final test segment (later recordings of the same 14 people; retrospective, inspected) | B13: Ridge dynamic + profile | C13: 30 | D13: macro per participant | E13: =IF(AND(ISNUMBER(Sources!$C$13)),Sources!$C$13,"unavailable") | F13: =IF(AND(ISNUMBER(Sources!$C$5)),Sources!$C$5,"unavailable") | G13: =IF(AND(ISNUMBER(E13),ISNUMBER(F13)),E13-F13,"unavailable") | H13: =IF(AND(ISNUMBER(E13),ISNUMBER(F13)),(E13-F13)/F13*100,"unavailable") | I13: =IF(AND(ISNUMBER(Sources!$C$14)),Sources!$C$14,"unavailable") | J13: — | K13: — | L13: — | N13: fus.ridgep.mae30; fus.pers.mae30; fus.ridgep.rmse30
A14: Serving model, final test segment (later recordings of the same 14 people; retrospective, inspected) | B14: Ridge dynamic + profile | C14: 60 | D14: macro per participant | E14: =IF(AND(ISNUMBER(Sources!$C$15)),Sources!$C$15,"unavailable") | F14: =IF(AND(ISNUMBER(Sources!$C$7)),Sources!$C$7,"unavailable") | G14: =IF(AND(ISNUMBER(E14),ISNUMBER(F14)),E14-F14,"unavailable") | H14: =IF(AND(ISNUMBER(E14),ISNUMBER(F14)),(E14-F14)/F14*100,"unavailable") | I14: =IF(AND(ISNUMBER(Sources!$C$16)),Sources!$C$16,"unavailable") | J14: — | K14: — | L14: — | N14: fus.ridgep.mae60; fus.pers.mae60; fus.ridgep.rmse60
A15: Serving model, final test segment (later recordings of the same 14 people; retrospective, inspected) | B15: Linear trend | C15: 30 | D15: macro per participant | E15: =IF(AND(ISNUMBER(Sources!$C$9)),Sources!$C$9,"unavailable") | F15: =IF(AND(ISNUMBER(Sources!$C$5)),Sources!$C$5,"unavailable") | G15: =IF(AND(ISNUMBER(E15),ISNUMBER(F15)),E15-F15,"unavailable") | H15: =IF(AND(ISNUMBER(E15),ISNUMBER(F15)),(E15-F15)/F15*100,"unavailable") | I15: =IF(AND(ISNUMBER(Sources!$C$10)),Sources!$C$10,"unavailable") | J15: — | K15: — | L15: — | N15: fus.trend.mae30; fus.pers.mae30; fus.trend.rmse30
A16: Serving model, final test segment (later recordings of the same 14 people; retrospective, inspected) | B16: Linear trend | C16: 60 | D16: macro per participant | E16: =IF(AND(ISNUMBER(Sources!$C$11)),Sources!$C$11,"unavailable") | F16: =IF(AND(ISNUMBER(Sources!$C$7)),Sources!$C$7,"unavailable") | G16: =IF(AND(ISNUMBER(E16),ISNUMBER(F16)),E16-F16,"unavailable") | H16: =IF(AND(ISNUMBER(E16),ISNUMBER(F16)),(E16-F16)/F16*100,"unavailable") | I16: =IF(AND(ISNUMBER(Sources!$C$12)),Sources!$C$12,"unavailable") | J16: — | K16: — | L16: — | N16: fus.trend.mae60; fus.pers.mae60; fus.trend.rmse60
A17: Serving model, final test segment (later recordings of the same 14 people; retrospective, inspected) | B17: Persistence | C17: 30 | D17: macro per participant | E17: =IF(AND(ISNUMBER(Sources!$C$5)),Sources!$C$5,"unavailable") | F17: =IF(AND(ISNUMBER(Sources!$C$5)),Sources!$C$5,"unavailable") | G17: =IF(AND(ISNUMBER(E17),ISNUMBER(F17)),E17-F17,"unavailable") | H17: =IF(AND(ISNUMBER(E17),ISNUMBER(F17)),(E17-F17)/F17*100,"unavailable") | I17: =IF(AND(ISNUMBER(Sources!$C$6)),Sources!$C$6,"unavailable") | J17: — | K17: — | L17: — | N17: fus.pers.mae30; fus.pers.mae30; fus.pers.rmse30
A18: Serving model, final test segment (later recordings of the same 14 people; retrospective, inspected) | B18: Persistence | C18: 60 | D18: macro per participant | E18: =IF(AND(ISNUMBER(Sources!$C$7)),Sources!$C$7,"unavailable") | F18: =IF(AND(ISNUMBER(Sources!$C$7)),Sources!$C$7,"unavailable") | G18: =IF(AND(ISNUMBER(E18),ISNUMBER(F18)),E18-F18,"unavailable") | H18: =IF(AND(ISNUMBER(E18),ISNUMBER(F18)),(E18-F18)/F18*100,"unavailable") | I18: =IF(AND(ISNUMBER(Sources!$C$8)),Sources!$C$8,"unavailable") | J18: — | K18: — | L18: — | N18: fus.pers.mae60; fus.pers.mae60; fus.pers.rmse60
A19: Participant-held-out internal (14 CGMacros people, each held out once; previously inspected) (D-032) | B19: Selected research procedure (Ridge CGM-only in 4/5 folds) | C19: 30 | D19: macro per participant | E19: =IF(AND(ISNUMBER(Sources!$C$191)),Sources!$C$191,"unavailable") | F19: =IF(AND(ISNUMBER(Sources!$C$193)),Sources!$C$193,"unavailable") | G19: =IF(AND(ISNUMBER(E19),ISNUMBER(F19)),E19-F19,"unavailable") | H19: =IF(AND(ISNUMBER(E19),ISNUMBER(F19)),(E19-F19)/F19*100,"unavailable") | I19: not in source | J19: — | K19: — | L19: — | M19: Not served | N19: nest.sel.mae30; nest.pers.mae30
A20: Participant-held-out internal (14 CGMacros people, each held out once; previously inspected) (D-032) | B20: Selected research procedure (Ridge CGM-only in 4/5 folds) | C20: 60 | D20: macro per participant | E20: =IF(AND(ISNUMBER(Sources!$C$192)),Sources!$C$192,"unavailable") | F20: =IF(AND(ISNUMBER(Sources!$C$194)),Sources!$C$194,"unavailable") | G20: =IF(AND(ISNUMBER(E20),ISNUMBER(F20)),E20-F20,"unavailable") | H20: =IF(AND(ISNUMBER(E20),ISNUMBER(F20)),(E20-F20)/F20*100,"unavailable") | I20: not in source | J20: — | K20: — | L20: — | M20: Not served | N20: nest.sel.mae60; nest.pers.mae60
A21: Participant-held-out internal (14 CGMacros people, each held out once; previously inspected) (D-032) | B21: v2 recipe refit per fold | C21: 30 | D21: macro per participant | E21: =IF(AND(ISNUMBER(Sources!$C$195)),Sources!$C$195,"unavailable") | F21: =IF(AND(ISNUMBER(Sources!$C$193)),Sources!$C$193,"unavailable") | G21: =IF(AND(ISNUMBER(E21),ISNUMBER(F21)),E21-F21,"unavailable") | H21: =IF(AND(ISNUMBER(E21),ISNUMBER(F21)),(E21-F21)/F21*100,"unavailable") | I21: not in source | J21: — | K21: — | L21: — | M21: Not served | N21: nest.v2.mae30; nest.pers.mae30
A22: Participant-held-out internal (14 CGMacros people, each held out once; previously inspected) (D-032) | B22: v2 recipe refit per fold | C22: 60 | D22: macro per participant | E22: =IF(AND(ISNUMBER(Sources!$C$196)),Sources!$C$196,"unavailable") | F22: =IF(AND(ISNUMBER(Sources!$C$194)),Sources!$C$194,"unavailable") | G22: =IF(AND(ISNUMBER(E22),ISNUMBER(F22)),E22-F22,"unavailable") | H22: =IF(AND(ISNUMBER(E22),ISNUMBER(F22)),(E22-F22)/F22*100,"unavailable") | I22: not in source | J22: — | K22: — | L22: — | M22: Not served | N22: nest.v2.mae60; nest.pers.mae60
A23: External ShanghaiT2DM, 98 people, CGM-only procedure (not the serving fusion model) (D-032) | B23: 15-min LightGBM, CGM only | C23: 30 | D23: macro per participant | E23: =IF(AND(ISNUMBER(Sources!$C$201)),Sources!$C$201,"unavailable") | F23: =IF(AND(ISNUMBER(Sources!$C$202)),Sources!$C$202,"unavailable") | G23: =IF(AND(ISNUMBER(E23),ISNUMBER(F23)),E23-F23,"unavailable") | H23: =IF(AND(ISNUMBER(E23),ISNUMBER(F23)),(E23-F23)/F23*100,"unavailable") | I23: not in source | J23: =IF(AND(ISNUMBER(Sources!$C$203)),Sources!$C$203,"unavailable") | K23: =IF(AND(ISNUMBER(Sources!$C$204)),Sources!$C$204,"unavailable") | L23: =IF(AND(ISNUMBER(Sources!$C$205)),Sources!$C$205,"unavailable") | M23: Not the fusion model | N23: ext.cand.mae30; ext.pers.mae30; ext.cmp.mean_diff30; ext.cmp.lo30; ext.cmp.hi30
A24: External ShanghaiT2DM, 98 people, CGM-only procedure (not the serving fusion model) (D-032) | B24: 15-min LightGBM, CGM only | C24: 60 | D24: macro per participant | E24: =IF(AND(ISNUMBER(Sources!$C$213)),Sources!$C$213,"unavailable") | F24: =IF(AND(ISNUMBER(Sources!$C$214)),Sources!$C$214,"unavailable") | G24: =IF(AND(ISNUMBER(E24),ISNUMBER(F24)),E24-F24,"unavailable") | H24: =IF(AND(ISNUMBER(E24),ISNUMBER(F24)),(E24-F24)/F24*100,"unavailable") | I24: not in source | J24: =IF(AND(ISNUMBER(Sources!$C$215)),Sources!$C$215,"unavailable") | K24: =IF(AND(ISNUMBER(Sources!$C$216)),Sources!$C$216,"unavailable") | L24: =IF(AND(ISNUMBER(Sources!$C$217)),Sources!$C$217,"unavailable") | M24: Not the fusion model | N24: ext.cand.mae60; ext.pers.mae60; ext.cmp.mean_diff60; ext.cmp.lo60; ext.cmp.hi60
A25: Participant-held-out internal (14 CGMacros people, each held out once; previously inspected) (D-043) | B25: Two-hour selected procedure, personalised | C25: 30 | D25: macro per participant | E25: =IF(AND(ISNUMBER(Sources!$C$224)),Sources!$C$224,"unavailable") | F25: =IF(AND(ISNUMBER(Sources!$C$225)),Sources!$C$225,"unavailable") | G25: =IF(AND(ISNUMBER(E25),ISNUMBER(F25)),E25-F25,"unavailable") | H25: =IF(AND(ISNUMBER(E25),ISNUMBER(F25)),(E25-F25)/F25*100,"unavailable") | I25: not in source | J25: — | K25: — | L25: — | M25: Not served | N25: 2h.sel.mae30; 2h.pers.mae30
A26: External ShanghaiT2DM, 98 people, CGM-only procedure (not the serving fusion model) (D-045) | B26: 15-min LightGBM refit for 120 min | C26: 30 | D26: macro per participant | E26: =IF(AND(ISNUMBER(Sources!$C$247)),Sources!$C$247,"unavailable") | F26: =IF(AND(ISNUMBER(Sources!$C$248)),Sources!$C$248,"unavailable") | G26: =IF(AND(ISNUMBER(E26),ISNUMBER(F26)),E26-F26,"unavailable") | H26: =IF(AND(ISNUMBER(E26),ISNUMBER(F26)),(E26-F26)/F26*100,"unavailable") | I26: not in source | J26: — | K26: — | L26: — | M26: Second opening of the cohort | N26: 2hx.mae30; 2hx.pers30
A27: Participant-held-out internal (14 CGMacros people, each held out once; previously inspected) (D-043) | B27: Two-hour selected procedure, personalised | C27: 60 | D27: macro per participant | E27: =IF(AND(ISNUMBER(Sources!$C$226)),Sources!$C$226,"unavailable") | F27: =IF(AND(ISNUMBER(Sources!$C$227)),Sources!$C$227,"unavailable") | G27: =IF(AND(ISNUMBER(E27),ISNUMBER(F27)),E27-F27,"unavailable") | H27: =IF(AND(ISNUMBER(E27),ISNUMBER(F27)),(E27-F27)/F27*100,"unavailable") | I27: not in source | J27: — | K27: — | L27: — | M27: Not served | N27: 2h.sel.mae60; 2h.pers.mae60
A28: External ShanghaiT2DM, 98 people, CGM-only procedure (not the serving fusion model) (D-045) | B28: 15-min LightGBM refit for 120 min | C28: 60 | D28: macro per participant | E28: =IF(AND(ISNUMBER(Sources!$C$249)),Sources!$C$249,"unavailable") | F28: =IF(AND(ISNUMBER(Sources!$C$250)),Sources!$C$250,"unavailable") | G28: =IF(AND(ISNUMBER(E28),ISNUMBER(F28)),E28-F28,"unavailable") | H28: =IF(AND(ISNUMBER(E28),ISNUMBER(F28)),(E28-F28)/F28*100,"unavailable") | I28: not in source | J28: — | K28: — | L28: — | M28: Second opening of the cohort | N28: 2hx.mae60; 2hx.pers60
A29: Participant-held-out internal (14 CGMacros people, each held out once; previously inspected) (D-043) | B29: Two-hour selected procedure, personalised | C29: 120 | D29: macro per participant | E29: =IF(AND(ISNUMBER(Sources!$C$228)),Sources!$C$228,"unavailable") | F29: =IF(AND(ISNUMBER(Sources!$C$229)),Sources!$C$229,"unavailable") | G29: =IF(AND(ISNUMBER(E29),ISNUMBER(F29)),E29-F29,"unavailable") | H29: =IF(AND(ISNUMBER(E29),ISNUMBER(F29)),(E29-F29)/F29*100,"unavailable") | I29: not in source | J29: =IF(AND(ISNUMBER(Sources!$C$230)),Sources!$C$230,"unavailable") | K29: =IF(AND(ISNUMBER(Sources!$C$231)),Sources!$C$231,"unavailable") | L29: =IF(AND(ISNUMBER(Sources!$C$232)),Sources!$C$232,"unavailable") | M29: Not served | N29: 2h.sel.mae120; 2h.pers.mae120; 2h.cmp.d; 2h.cmp.lo; 2h.cmp.hi
